Workbook

Sheet HOME
A1: FIELD FORCE OPTIMIZER
A3: Plánování a řízení terénních techniků
A5: DALŠÍ KROK
A6: =IFS(G10="❌ Chybí","1) Vlož export POS a SalesApp do RAW_DATA / POS_STATUS_IMPORT / SALESAPP_IMPORT a spusť Import Engine",G11="❌ Chybí","2) Vytvoř nebo prodluž kampaň v ACTIVITY_PLAN",G12="❌ Chybí","3) Spusť Planning Engine - vytvoří rozpis technikům",G13="❌ Chybí","4) Publikuj plán (Publish Engine)",G14="❌ Chybí","5) Spusť Compliance a Advisor Engine - vyhodnotí skutečné návštěvy proti plánu",TRUE,"✅ Vše hotovo pro tento týden - sleduj plnění na DASHBOARD")
A9: STAV PROCESU
A10: 1 | B10: IMPORT DAT — Nahraj export POS a SalesApp | G10: =IF(COUNTA(POS_MASTER!A:A)>1,"✅ Hotovo","❌ Chybí") | H10: Otevřít →
A11: 2 | B11: PLÁN KAMPANÍ — Nastav kampaně v ACTIVITY_PLAN | G11: =IF(COUNTA(ACTIVITY_PLAN!A:A)>1,"✅ Hotovo","❌ Chybí") | H11: Otevřít →
A12: 3 | B12: ROZPIS TECHNIKŮ — Planning Engine vytvoří rozpis | G12: =IF(COUNTA(MANAGER_PLAN!A:A)>1,"✅ Hotovo","❌ Chybí") | H12: Otevřít →
A13: 4 | B13: PUBLIKACE — Publish Engine odešle plán technikům | G13: =IF(COUNTIF(PLAN_LIFECYCLE!C:C,"Published")+COUNTIF(PLAN_LIFECYCLE!C:C,"Active")>0,"✅ Hotovo","❌ Chybí") | H13: ⚙ Automatizace
A14: 5 | B14: VYHODNOCENÍ — Compliance + Advisor Engine porovná realitu s plánem | G14: =IF(COUNTA(COMPLIANCE_LOG!A:A)>1,"✅ Hotovo","❌ Chybí") | H14: Otevřít →
A15: 6 | B15: DASHBOARD — Sleduj plnění, KPI a upozornění | G15: =IF(COUNTA(DASHBOARD!A5:A500)>0,"✅ Aktivní","⏳ Čeká na první běh") | H15: Otevřít →
A17: TENTO TÝDEN
B18: Aktuální kampaň týden | D18: POS v systému | F18: Naplánováno návštěv
B19: =IFERROR(VLOOKUP("CAMPAIGN_START_WEEK",CONTROL!A:B,2,FALSE),"-") | D19: =COUNTA(POS_MASTER!A:A)-1 | F19: =COUNTA(MANAGER_PLAN!A:A)-1
B21: POS pokryto plánem | D21: Techniků naplánováno | F21: Compliance (splněno / nesplněno)
B22: =SUMPRODUCT((MANAGER_PLAN!E2:E200000<>"")/COUNTIF(MANAGER_PLAN!E2:E200000,MANAGER_PLAN!E2:E200000&"")) | D22: =SUMPRODUCT((MANAGER_PLAN!D2:D200000<>"")/COUNTIF(MANAGER_PLAN!D2:D200000,MANAGER_PLAN!D2:D200000&"")) | F22: =DASHBOARD!C3&" / "&DASHBOARD!D3
B24: Aktivní kampaně | D24: Otevřená upozornění
B25: =COUNTA(ACTIVITY_PLAN!A:A)-1 | D25: =DASHBOARD!E3
A27: RYCHLÁ NAVIGACE
A28: DASHBOARD | C28: TECHNICIAN_PLAN | E28: POS_MASTER | G28: ACTIVITY_PLAN
A30: JAK ČÍST BARVY
B31: Editovatelné - sem zapisuješ | D31: Systémové - počítá engine | F31: Sem vlož export | H31: Výsledek plánování
A33: PRVNÍ SPUŠTĚNÍ
B34: 1) Otevři tento sešit v Excelu na webu (OneDrive/SharePoint) - Office Scripts to vyžadují.
B35: 2) Záložka Automatizace → New Script → vlož obsah office-scripts/ImportEngine.ts → Spustit.
B36: 3) Opakuj pro PlanningEngine.ts, PublishEngine.ts, ComplianceEngine.ts, AdvisorEngine.ts, ReportingEngine.ts.

Sheet DASHBOARD
A1: DASHBOARD
B2: Aktivní POS | C2: Splněno včas | D2: Nesplněno | E2: Otevřené alerty

Sheet TECHNICIAN_PLAN
A1: DATUM | B1: DEN | C1: TECHNIK | D1: POS | E1: NÁZEV PROVOZOVNY | F1: ULICE | G1: MĚSTO | H1: OBLAST | I1: AKTIVITA | J1: POZNÁMKA
A2: =IF($D2="","",MANAGER_PLAN!B2) | B2: =IF($D2="","",MANAGER_PLAN!C2) | C2: =IF(MANAGER_PLAN!E2="","",MANAGER_PLAN!D2) | D2: =IF(MANAGER_PLAN!E2="","",MANAGER_PLAN!E2) | E2: =IF($D2="","",MANAGER_PLAN!G2) | F2: =IF($D2="","",TRIM(MANAGER_PLAN!H2&" "&MANAGER_PLAN!I2)) | G2: =IF($D2="","",MANAGER_PLAN!J2) | H2: =IF($D2="","",MANAGER_PLAN!K2) | I2: =IF($D2="","",TRIM(IF(MANAGER_PLAN!N2<>"","LOS: "&MANAGER_PLAN!N2&" ","")&IF(MANAGER_PLAN!O2<>"","LOT: "&MANAGER_PLAN!O2,""))) | J2: =IF($D2="","",IFERROR(VLOOKUP($D2,POS_MASTER!$A:$AK,37,FALSE),""))
A3: =IF($D3="","",MANAGER_PLAN!B3) | B3: =IF($D3="","",MANAGER_PLAN!C3) | C3: =IF(MANAGER_PLAN!E3="","",MANAGER_PLAN!D3) | D3: =IF(MANAGER_PLAN!E3="","",MANAGER_PLAN!E3) | E3: =IF($D3="","",MANAGER_PLAN!G3) | F3: =IF($D3="","",TRIM(MANAGER_PLAN!H3&" "&MANAGER_PLAN!I3)) | G3: =IF($D3="","",MANAGER_PLAN!J3) | H3: =IF($D3="","",MANAGER_PLAN!K3) | I3: =IF($D3="","",TRIM(IF(MANAGER_PLAN!N3<>"","LOS: "&MANAGER_PLAN!N3&" ","")&IF(MANAGER_PLAN!O3<>"","LOT: "&MANAGER_PLAN!O3,""))) | J3: =IF($D3="","",IFERROR(VLOOKUP($D3,POS_MASTER!$A:$AK,37,FALSE),""))
A4: =IF($D4="","",MANAGER_PLAN!B4) | B4: =IF($D4="","",MANAGER_PLAN!C4) | C4: =IF(MANAGER_PLAN!E4="","",MANAGER_PLAN!D4) | D4: =IF(MANAGER_PLAN!E4="","",MANAGER_PLAN!E4) | E4: =IF($D4="","",MANAGER_PLAN!G4) | F4: =IF($D4="","",TRIM(MANAGER_PLAN!H4&" "&MANAGER_PLAN!I4)) | G4: =IF($D4="","",MANAGER_PLAN!J4) | H4: =IF($D4="","",MANAGER_PLAN!K4) | I4: =IF($D4="","",TRIM(IF(MANAGER_PLAN!N4<>"","LOS: "&MANAGER_PLAN!N4&" ","")&IF(MANAGER_PLAN!O4<>"","LOT: "&MANAGER_PLAN!O4,""))) | J4: =IF($D4="","",IFERROR(VLOOKUP($D4,POS_MASTER!$A:$AK,37,FALSE),""))
A5: =IF($D5="","",MANAGER_PLAN!B5) | B5: =IF($D5="","",MANAGER_PLAN!C5) | C5: =IF(MANAGER_PLAN!E5="","",MANAGER_PLAN!D5) | D5: =IF(MANAGER_PLAN!E5="","",MANAGER_PLAN!E5) | E5: =IF($D5="","",MANAGER_PLAN!G5) | F5: =IF($D5="","",TRIM(MANAGER_PLAN!H5&" "&MANAGER_PLAN!I5)) | G5: =IF($D5="","",MANAGER_PLAN!J5) | H5: =IF($D5="","",MANAGER_PLAN!K5) | I5: =IF($D5="","",TRIM(IF(MANAGER_PLAN!N5<>"","LOS: "&MANAGER_PLAN!N5&" ","")&IF(MANAGER_PLAN!O5<>"","LOT: "&MANAGER_PLAN!O5,""))) | J5: =IF($D5="","",IFERROR(VLOOKUP($D5,POS_MASTER!$A:$AK,37,FALSE),""))
A6: =IF($D6="","",MANAGER_PLAN!B6) | B6: =IF($D6="","",MANAGER_PLAN!C6) | C6: =IF(MANAGER_PLAN!E6="","",MANAGER_PLAN!D6) | D6: =IF(MANAGER_PLAN!E6="","",MANAGER_PLAN!E6) | E6: =IF($D6="","",MANAGER_PLAN!G6) | F6: =IF($D6="","",TRIM(MANAGER_PLAN!H6&" "&MANAGER_PLAN!I6)) | G6: =IF($D6="","",MANAGER_PLAN!J6) | H6: =IF($D6="","",MANAGER_PLAN!K6) | I6: =IF($D6="","",TRIM(IF(MANAGER_PLAN!N6<>"","LOS: "&MANAGER_PLAN!N6&" ","")&IF(MANAGER_PLAN!O6<>"","LOT: "&MANAGER_PLAN!O6,""))) | J6: =IF($D6="","",IFERROR(VLOOKUP($D6,POS_MASTER!$A:$AK,37,FALSE),""))
A7: =IF($D7="","",MANAGER_PLAN!B7) | B7: =IF($D7="","",MANAGER_PLAN!C7) | C7: =IF(MANAGER_PLAN!E7="","",MANAGER_PLAN!D7) | D7: =IF(MANAGER_PLAN!E7="","",MANAGER_PLAN!E7) | E7: =IF($D7="","",MANAGER_PLAN!G7) | F7: =IF($D7="","",TRIM(MANAGER_PLAN!H7&" "&MANAGER_PLAN!I7)) | G7: =IF($D7="","",MANAGER_PLAN!J7) | H7: =IF($D7="","",MANAGER_PLAN!K7) | I7: =IF($D7="","",TRIM(IF(MANAGER_PLAN!N7<>"","LOS: "&MANAGER_PLAN!N7&" ","")&IF(MANAGER_PLAN!O7<>"","LOT: "&MANAGER_PLAN!O7,""))) | J7: =IF($D7="","",IFERROR(VLOOKUP($D7,POS_MASTER!$A:$AK,37,FALSE),""))
A8: =IF($D8="","",MANAGER_PLAN!B8) | B8: =IF($D8="","",MANAGER_PLAN!C8) | C8: =IF(MANAGER_PLAN!E8="","",MANAGER_PLAN!D8) | D8: =IF(MANAGER_PLAN!E8="","",MANAGER_PLAN!E8) | E8: =IF($D8="","",MANAGER_PLAN!G8) | F8: =IF($D8="","",TRIM(MANAGER_PLAN!H8&" "&MANAGER_PLAN!I8)) | G8: =IF($D8="","",MANAGER_PLAN!J8) | H8: =IF($D8="","",MANAGER_PLAN!K8) | I8: =IF($D8="","",TRIM(IF(MANAGER_PLAN!N8<>"","LOS: "&MANAGER_PLAN!N8&" ","")&IF(MANAGER_PLAN!O8<>"","LOT: "&MANAGER_PLAN!O8,""))) | J8: =IF($D8="","",IFERROR(VLOOKUP($D8,POS_MASTER!$A:$AK,37,FALSE),""))
A9: =IF($D9="","",MANAGER_PLAN!B9) | B9: =IF($D9="","",MANAGER_PLAN!C9) | C9: =IF(MANAGER_PLAN!E9="","",MANAGER_PLAN!D9) | D9: =IF(MANAGER_PLAN!E9="","",MANAGER_PLAN!E9) | E9: =IF($D9="","",MANAGER_PLAN!G9) | F9: =IF($D9="","",TRIM(MANAGER_PLAN!H9&" "&MANAGER_PLAN!I9)) | G9: =IF($D9="","",MANAGER_PLAN!J9) | H9: =IF($D9="","",MANAGER_PLAN!K9) | I9: =IF($D9="","",TRIM(IF(MANAGER_PLAN!N9<>"","LOS: "&MANAGER_PLAN!N9&" ","")&IF(MANAGER_PLAN!O9<>"","LOT: "&MANAGER_PLAN!O9,""))) | J9: =IF($D9="","",IFERROR(VLOOKUP($D9,POS_MASTER!$A:$AK,37,FALSE),""))
A10: =IF($D10="","",MANAGER_PLAN!B10) | B10: =IF($D10="","",MANAGER_PLAN!C10) | C10: =IF(MANAGER_PLAN!E10="","",MANAGER_PLAN!D10) | D10: =IF(MANAGER_PLAN!E10="","",MANAGER_PLAN!E10) | E10: =IF($D10="","",MANAGER_PLAN!G10) | F10: =IF($D10="","",TRIM(MANAGER_PLAN!H10&" "&MANAGER_PLAN!I10)) | G10: =IF($D10="","",MANAGER_PLAN!J10) | H10: =IF($D10="","",MANAGER_PLAN!K10) | I10: =IF($D10="","",TRIM(IF(MANAGER_PLAN!N10<>"","LOS: "&MANAGER_PLAN!N10&" ","")&IF(MANAGER_PLAN!O10<>"","LOT: "&MANAGER_PLAN!O10,""))) | J10: =IF($D10="","",IFERROR(VLOOKUP($D10,POS_MASTER!$A:$AK,37,FALSE),""))
A11: =IF($D11="","",MANAGER_PLAN!B11) | B11: =IF($D11="","",MANAGER_PLAN!C11) | C11: =IF(MANAGER_PLAN!E11="","",MANAGER_PLAN!D11) | D11: =IF(MANAGER_PLAN!E11="","",MANAGER_PLAN!E11) | E11: =IF($D11="","",MANAGER_PLAN!G11) | F11: =IF($D11="","",TRIM(MANAGER_PLAN!H11&" "&MANAGER_PLAN!I11)) | G11: =IF($D11="","",MANAGER_PLAN!J11) | H11: =IF($D11="","",MANAGER_PLAN!K11) | I11: =IF($D11="","",TRIM(IF(MANAGER_PLAN!N11<>"","LOS: "&MANAGER_PLAN!N11&" ","")&IF(MANAGER_PLAN!O11<>"","LOT: "&MANAGER_PLAN!O11,""))) | J11: =IF($D11="","",IFERROR(VLOOKUP($D11,POS_MASTER!$A:$AK,37,FALSE),""))
A12: =IF($D12="","",MANAGER_PLAN!B12) | B12: =IF($D12="","",MANAGER_PLAN!C12) | C12: =IF(MANAGER_PLAN!E12="","",MANAGER_PLAN!D12) | D12: =IF(MANAGER_PLAN!E12="","",MANAGER_PLAN!E12) | E12: =IF($D12="","",MANAGER_PLAN!G12) | F12: =IF($D12="","",TRIM(MANAGER_PLAN!H12&" "&MANAGER_PLAN!I12)) | G12: =IF($D12="","",MANAGER_PLAN!J12) | H12: =IF($D12="","",MANAGER_PLAN!K12) | I12: =IF($D12="","",TRIM(IF(MANAGER_PLAN!N12<>"","LOS: "&MANAGER_PLAN!N12&" ","")&IF(MANAGER_PLAN!O12<>"","LOT: "&MANAGER_PLAN!O12,""))) | J12: =IF($D12="","",IFERROR(VLOOKUP($D12,POS_MASTER!$A:$AK,37,FALSE),""))
A13: =IF($D13="","",MANAGER_PLAN!B13) | B13: =IF($D13="","",MANAGER_PLAN!C13) | C13: =IF(MANAGER_PLAN!E13="","",MANAGER_PLAN!D13) | D13: =IF(MANAGER_PLAN!E13="","",MANAGER_PLAN!E13) | E13: =IF($D13="","",MANAGER_PLAN!G13) | F13: =IF($D13="","",TRIM(MANAGER_PLAN!H13&" "&MANAGER_PLAN!I13)) | G13: =IF($D13="","",MANAGER_PLAN!J13) | H13: =IF($D13="","",MANAGER_PLAN!K13) | I13: =IF($D13="","",TRIM(IF(MANAGER_PLAN!N13<>"","LOS: "&MANAGER_PLAN!N13&" ","")&IF(MANAGER_PLAN!O13<>"","LOT: "&MANAGER_PLAN!O13,""))) | J13: =IF($D13="","",IFERROR(VLOOKUP($D13,POS_MASTER!$A:$AK,37,FALSE),""))
... A3000: =IF($D3000="","",MANAGER_PLAN!B3000) | B3000: =IF($D3000="","",MANAGER_PLAN!C3000) | C3000: =IF(MANAGER_PLAN!E3000="","",MANAGER_PLAN!D3000) | D3000: =IF(MANAGER_PLAN!E3000="","",MANAGER_PLAN!E3000) | E3000: =IF($D3000="","",MANAGER_PLAN!G3000) | F3000: =IF($D3000="","",TRIM(MANAGER_PLAN!H3000&" "&MANAGER_PLAN!I3000)) | G3000: =IF($D3000="","",MANAGER_PLAN!J3000) | H3000: =IF($D3000="","",MANAGER_PLAN!K3000) | I3000: =IF($D3000="","",TRIM(IF(MANAGER_PLAN!N3000<>"","LOS: "&MANAGER_PLAN!N3000&" ","")&IF(MANAGER_PLAN!O3000<>"","LOT: "&MANAGER_PLAN!O3000,""))) | J3000: =IF($D3000="","",IFERROR(VLOOKUP($D3000,POS_MASTER!$A:$AK,37,FALSE),""))

Sheet POS_MASTER
A1: posId | B1: terminalId | C1: market | D1: category | E1: terminalType | F1: classification | G1: nazev | H1: area | I1: posArea | J1: street | K1: houseNumber | L1: city | M1: gpsX | N1: gpsY | O1: assignedTechnician | P1: ppt | Q1: status | R1: closedSinceWeek | S1: closedSinceYear | T1: currentLosActivity | U1: currentLotActivity | V1: targetLosActivity | W1: targetLotActivity | X1: lastRealVisitDate | Y1: lastRealVisitWeek | Z1: lastPlannedVisitDate | AA1: weeksSinceLastVisit | AB1: visitCountThisCampaign | AC1: businessScore | AD1: plannerStatus | AE1: assignedWeek | AF1: assignedDay | AG1: gpsGroup | AH1: managerOverrideType | AI1: managerOverridePriority | AJ1: managerOverrideTechnician | AK1: plannerNotes | AL1: importedAt | AM1: updatedAt

Sheet ACTIVITY_PLAN
A1: TYPE | B1: ACTIVITY | C1: START_WEEK | D1: END_WEEK | E1: PRIORITY | F1: OVERRIDE_GAP | G1: ODHAD_NAVSTEV_ZA_KAMPAN | I1: REFERENČNÍ HODNOTY (pro odhad) | K1: ČASOVÁ OSA KAMPANÍ (týden) | L1: 27 | M1: 28 | N1: 29 | O1: 30 | P1: 31 | Q1: 32 | R1: 33 | S1: 34 | T1: 35 | U1: 36 | V1: 37 | W1: 38
A2: LOS | B2: Gems | C2: 31 | D2: 35 | E2: 5 | F2: NO | G2: =IF($C2="","",($D2-$C2+1)*$J$2*$J$5) | I2: Počet techniků (distinct, z POS_MASTER) | J2: =SUMPRODUCT((POS_MASTER!O2:O20000<>"")/COUNTIF(POS_MASTER!O2:O20000,POS_MASTER!O2:O20000&""))
A3: LOT | B3: Sportka | C3: 30 | D3: 35 | E3: 5 | F3: NO | G3: =IF($C3="","",($D3-$C3+1)*$J$2*$J$5) | I3: Cílový počet návštěv/den (CONTROL.TARGET_VISITS_DAY) | J3: =IFERROR(VLOOKUP("TARGET_VISITS_DAY",CONTROL!A:B,2,FALSE),8)
I4: Průměr pracovních dní/týden (odhad vč. svátků) | J4: 4.8
I5: → Kapacita/technik/týden (řádky J3*J4) | J5: =J3*J4
L6: LOS | M6: =aktivní LOS kampaň v daném týdnu
L7: LOT | M7: =aktivní LOT kampaň v daném týdnu
L8: Souběh dvou kampaní ve stejném týdnu = obě barvy vidíš ve stejném sloupci u různých řádků (porovnej řádky svisle).

Sheet RAW_DATA
A1: Sem vloz export POS
A2: ČÍSLO TERMINÁLU | B2: POS | C2: TYP TERMINÁLU | D2: MARKET | E2: KATEGORIE | F2: KATEGORIZACE | G2: NAZEV PROVOZOVNY | H2: ULICE | I2: ČÍSLO POPISNÉ/ORIENTAČNÍ | J2: MĚSTO | K2: OBLAST | L2: POS AREA | M2: technik | N2: X | O2: Y | P2: PTT
A3: 11041007 | B3: 81041001 | C3: VELKY TERMINAL | D3: CORN | E3: 9PODNIKC | F3: A | G3: Allwyn Česko a.s. | H3: Obchodní | I3: 111 | J3: ČESTLICE | K3: Praha-východ | L3: RSA | M3: Myslivec Jan | N3: 50.003450 | O3: 14.573660 | P3: 832221.35
A4: 11041008 | B4: 81041008 | C4: VELKY TERMINAL | D4: CORN | E4: 9PODNIKC | F4: A | G4: Allwyn Česko a.s. | H4: Chlumecká (CČM) | I4: 765/6 | J4: PRAHA 9 - ČERNÝ MOST | K4: Praha | L4: RSA | M4: Hrubý Jiří | N4: 50.108731 | O4: 14.583760 | P4: 638316.23
A5: 11041009 | B5: 81041009 | C5: VELKY TERMINAL | D5: CORN | E5: 9PODNIKC | F5: A | G5: Allwyn Česko a.s. | H5: Plzeňská (OC Nový Smíchov) | I5: 233/8 | J5: PRAHA 5 - SMÍCHOV | K5: Praha | L5: RSA | M5: Dosoudil Petr | N5: 50.073066 | O5: 14.402576 | P5: 530457.12
A6: 11902619 | B6: 81902607 | C6: VELKY TERMINAL | D6: KA PARTNERS | E6: 1GECO | F6: A | G6: GECO, a.s. | H6: Kostelecká | I6: 823/77 | J6: PRAHA 9 - ČAKOVICE | K6: Praha | L6: RSA | M6: Hrubý Jiří | N6: 50.151164 | O6: 14.506775 | P6: 525747.65
A7: 14900237 | B7: 84900217 | C7: VELKY TERMINAL | D7: KA PARTNERS | E7: 1GECO | F7: A | G7: GECO, a.s. | H7: Tyršova | I7: 869 | J7: TRMICE | K7: Ústí nad Labem | L7: RSD | M7: Šticha Milan | N7: 50.651066 | O7: 14.000702 | P7: 481596.04
A8: 14900236 | B8: 84900218 | C8: VELKY TERMINAL | D8: KA PARTNERS | E8: 1GECO | F8: A | G8: GECO, a.s. | H8: Černovická | I8: 5430 | J8: CHOMUTOV | K8: Chomutov | L8: RSD | M8: Neubert Jaroslav | N8: 50.456788 | O8: 13.392793 | P8: 466819.15
A9: 13900322 | B9: 83900322 | C9: VELKY TERMINAL | D9: KA PARTNERS | E9: 1GECO | F9: A | G9: GECO, a.s. | H9: Obchodní | I9: 30 | J9: JENIŠOV - POD ROHEM | K9: Karlovy Vary | L9: RSC | M9: Beneš Lukáš | N9: 50.218669 | O9: 12.806046 | P9: 450976.73
A10: 11041015 | B10: 81041015 | C10: VELKY TERMINAL | D10: CORN | E10: 9PODNIKC | F10: A | G10: Allwyn Česko a.s. | H10: Roztylská | I10: 2321/19 | J10: PRAHA 4 - CHODOV | K10: Praha | L10: RSA | M10: Myslivec Jan | N10: 50.032097 | O10: 14.491007 | P10: 408567.77
A11: 17602253 | B11: 87602201 | C11: VELKY TERMINAL | D11: KA PARTNERS | E11: 1GECO | F11: A | G11: GECO, a.s. | H11: Výškovická | I11: 3086/44 | J11: OSTRAVA - ZÁBŘEH | K11: Ostrava-město | L11: RSG | M11: Dolníček Richard | N11: 49.799924 | O11: 18.231313 | P11: 405341.81
A12: 16900547 | B12: 86900520 | C12: VELKY TERMINAL | D12: KA PARTNERS | E12: 1GECO | F12: A | G12: GECO, a.s. | H12: Hradecká | I12: 408/40 | J12: BRNO - IVANOVICE | K12: Brno-město | L12: RSB | M12: Hanuš Robert | N12: 49.262010 | O12: 16.578590 | P12: 403813.19
A13: 17602250 | B13: 87602250 | C13: VELKY TERMINAL | D13: KA PARTNERS | E13: 1GECO | F13: A | G13: GECO, a.s. | H13: U Skleníků | I13: 1490/24 | J13: HAVÍŘOV - PROSTŘEDNÍ SUCHÁ | K13: Karviná | L13: RSG | M13: Brindžák Michal | N13: 49.790993 | O13: 18.441539 | P13: 403738.88
A14: 14900238 | B14: 84900211 | C14: VELKY TERMINAL | D14: KA PARTNERS | E14: 1GECO | F14: A | G14: GECO, a.s. | H14: Krušnohorská | I14: 3371/2 | J14: ÚSTÍ NAD LABEM - SEVERNÍ TERASA | K14: Ústí nad Labem | L14: RSD | M14: Šticha Milan | N14: 50.677500 | O14: 14.036815 | P14: 401217.19
... A129: 14900255 | B129: 84900255 | C129: VELKY TERMINAL | D129: KA PARTNERS | E129: 1GECO | F129: A | G129: GECO, a.s. | H129: Velebudická | I129: 3270 | J129: MOST | K129: Most | L129: RSD | M129: Neubert Jaroslav | N129: 50.485949 | O129: 13.655509 | P129: 238924.85
A130: 15900632 | B130: 85900632 | C130: VELKY TERMINAL | D130: KA PARTNERS | E130: 1GECO | F130: A | G130: GECO, a.s. | H130: Svitavská | J130: MORAVSKÁ TŘEBOVÁ - PŘEDMĚSTÍ | K130: Svitavy | L130: RSE | M130: Rek Lubomír | N130: 49.757025 | O130: 16.645940 | P130: 238214.35
A131: 16900532 | B131: 86900532 | C131: VELKY TERMINAL | D131: KA PARTNERS | E131: 1GECO | F131: A | G131: GECO, a.s. | H131: Jarošova | I131: 1234/2 | J131: ZNOJMO | K131: Znojmo | L131: RSB | M131: Koutný Roman | N131: 48.860205 | O131: 16.055529 | P131: 237800.65
A132: 11920332 | B132: 81920332 | C132: VELKY TERMINAL | D132: KA PARTNERS | E132: 1GECO | F132: A | G132: GECO, a.s. | H132: Zápská | I132: 2600 | J132: BRANDÝS NAD LABEM-STARÁ BOLESLAV | K132: Praha-východ | L132: RSA | M132: Myslivec Jan | N132: 50.178941 | O132: 14.669457 | P132: 237616.15
A133: 16900531 | B133: 86900531 | C133: VELKY TERMINAL | D133: KA PARTNERS | E133: 1GECO | F133: A | G133: GECO, a.s. | H133: Tř. Maršála Malinovského | I133: 1304 | J133: UHERSKÉ HRADIŠTĚ | K133: Uherské Hradiště | L133: RSE | M133: Modlitba Jakub | N133: 49.074316 | O133: 17.471008 | P133: 236957.54
A134: 17861401 | B134: 87861401 | C134: VELKY TERMINAL | D134: IDT | E134: 4OSTATNI | F134: A | G134: Irena Hofmannová | H134: Masarykovo nám. | I134: 3/3 | J134: NOVÝ JIČÍN | K134: Nový Jičín | L134: RSG | M134: Herman Petr | N134: 49.594396 | O134: 18.010160 | P134: 234851
A135: 15900620 | B135: 85900620 | C135: VELKY TERMINAL | D135: KA PARTNERS | E135: 1GECO | F135: A | G135: GECO, a.s. | H135: Bělohradská | I135: 3855 | J135: HAVLÍČKŮV BROD | K135: Havlíčkův Brod | L135: RSE | M135: Rek Lubomír | N135: 49.601560 | O135: 15.586081 | P135: 233138.54
A136: 17618705 | B136: 87618705 | C136: VELKY TERMINAL | D136: KA PARTNERS | E136: 1VALMONT | F136: A | G136: VALMONT CR, spol. s r.o. | H136: Vítkovická | I136: 3278/3 | J136: OSTRAVA - MORAVSKÁ OSTRAVA | K136: Ostrava-město | L136: RSG | M136: Gelnar Ivo | N136: 49.829249 | O136: 18.280392 | P136: 231460
A137: 11601020 | B137: 81601020 | C137: VELKY TERMINAL | D137: KA PARTNERS | E137: 1VALMONT | F137: A | G137: VALMONT CR, spol. s r.o. | H137: Budějovická | I137: 1667/64 | J137: PRAHA 4 - KRČ | K137: Praha | L137: RSA | M137: Myslivec Jan | N137: 50.043540 | O137: 14.449360 | P137: 231294.35
A138: 11920305 | B138: 81920305 | C138: VELKY TERMINAL | D138: KA PARTNERS | E138: 1GECO | F138: A | G138: GECO, a.s. | H138: Brodská | I138: 496 | J138: PŘÍBRAM - PŘÍBRAM V-ZDABOŘ | K138: Příbram | L138: RSA | M138: Fiedler Miroslav | N138: 49.666840 | O138: 13.998000 | P138: 231172.38
A139: 11915432 | B139: 81915432 | C139: VELKY TERMINAL | D139: KA PARTNERS | E139: 1PEAL | F139: A | G139: PEAL a.s. - Don Pealo | H139: Hornoměcholupská | I139: 763/123 | J139: PRAHA 10 - HORNÍ MĚCHOLUPY | K139: Praha | L139: RSA | M139: Česnek Miroslav | N139: 50.044128 | O139: 14.568769 | P139: 230746.38
A140: 15900625 | B140: 85900625 | C140: VELKY TERMINAL | D140: KA PARTNERS | E140: 1GECO | F140: A | G140: GECO, a.s. | H140: S. K. Neumanna | I140: 2819 | J140: PARDUBICE - ZELENÉ PŘEDMĚSTÍ | K140: Pardubice | L140: RSE | M140: Jareš Jaroslav | N140: 50.026279 | O140: 15.779414 | P140: 230687.58
A141: 17602259 | B141: 87602259 | C141: VELKY TERMINAL | D141: KA PARTNERS | E141: 1GECO | F141: A | G141: GECO, a.s. | H141: Nádražní | I141: 1939/4a | J141: KARVINÁ - FRYŠTÁT | K141: Karviná | L141: RSG | M141: Dolníček Richard | N141: 49.856513 | O141: 18.529617 | P141: 230656.77
A142: 17602237 | B142: 87602237 | C142: VELKY TERMINAL | D142: KA PARTNERS | E142: 1GECO | F142: A | G142: GECO, a.s. | H142: Lidická | I142: 1269 | J142: TŘINEC - LYŽBICE | K142: Frýdek-Místek | L142: RSG | M142: Herman Michal | N142: 49.669400 | O142: 18.676522 | P142: 230443.08
... A161: 14900227 | B161: 84900227 | C161: VELKY TERMINAL | D161: KA PARTNERS | E161: 1GECO | F161: A | G161: GECO, a.s. | H161: Dr. Milady Horákové | I161: 586/90a | J161: LIBEREC - LIBEREC VII-HORNÍ RŮŽODOL | K161: Liberec | L161: RSD | M161: Luňáček Jan | N161: 50.752592 | O161: 15.055210 | P161: 220744.23
A162: 14900260 | B162: 84900260 | C162: VELKY TERMINAL | D162: KA PARTNERS | E162: 1GECO | F162: A | G162: GECO, a.s. | H162: Siřejovická (Kaufland) | J162: LOVOSICE | K162: Litoměřice | L162: RSD | M162: Šticha Milan | N162: 50.506455 | O162: 14.052286 | P162: 220540.19
A163: 11920339 | B163: 81920339 | C163: VELKY TERMINAL | D163: KA PARTNERS | E163: 1GECO | F163: A | G163: GECO, a.s. - Albert Mladá Boleslav | H163: Jičínská | I163: 1349 | J163: MLADÁ BOLESLAV - MLADÁ BOLESLAV III | K163: Mladá Boleslav | L163: RSA | M163: Vlk Pavel | N163: 50.412176 | O163: 14.935967 | P163: 220178.08
A164: 12900604 | B164: 82900604 | C164: VELKY TERMINAL | D164: KA PARTNERS | E164: 1GECO | F164: A | G164: GECO, a.s. | H164: Katovická | I164: 1306 | J164: STRAKONICE - STRAKONICE I | K164: Strakonice | L164: RSB | M164: Štolba Jan | N164: 49.263747 | O164: 13.891257 | P164: 219862.12
A165: 11920310 | B165: 81920310 | C165: VELKY TERMINAL | D165: KA PARTNERS | E165: 1GECO | F165: A | G165: GECO, a.s. | H165: Ortenova | I165: 188 | J165: KUTNÁ HORA - ŠIPŠÍ | K165: Kutná Hora | L165: RSA | M165: Česnek Miroslav | N165: 49.960944 | O165: 15.283733 | P165: 219208.19
A166: 17602281 | B166: 87602281 | C166: VELKY TERMINAL | D166: KA PARTNERS | E166: 1GECO | F166: A | G166: GECO, a.s. | H166: Dr. Martínka | I166: 1617/10 | J166: OSTRAVA - HRABŮVKA | K166: Ostrava-město | L166: RSG | M166: Herman Michal | N166: 49.784894 | O166: 18.263193 | P166: 217682.96
A167: 16900537 | B167: 86900537 | C167: VELKY TERMINAL | D167: KA PARTNERS | E167: 1GECO | F167: A | G167: GECO, a.s. | H167: Chelčického | I167: 2376/7 | J167: ŽĎÁR NAD SÁZAVOU - ŽĎÁR NAD SÁZAVOU 6 | K167: Žďár nad Sázavou | L167: RSE | M167: Rek Lubomír | N167: 49.555185 | O167: 15.936994 | P167: 217503.54
A168: 11601005 | B168: 81601005 | C168: VELKY TERMINAL | D168: KA PARTNERS | E168: 1VALMONT | F168: A | G168: VALMONT CR, spol. s r.o. | H168: Vinohradská (Flora Sen) | I168: 2828/151 | J168: PRAHA 3 - ŽIŽKOV | K168: Praha | L168: RSA | M168: Myslivec Jan | N168: 50.078136 | O168: 14.461231 | P168: 217324.54
A169: 16900521 | B169: 86900521 | C169: VELKY TERMINAL | D169: KA PARTNERS | E169: 1GECO | F169: A | G169: GECO, a.s. | H169: Vídeňská | I169: 684/69 | J169: ZNOJMO | K169: Znojmo | L169: RSB | M169: Koutný Roman | N169: 48.845839 | O169: 16.059351 | P169: 217262.88
A170: 15900624 | B170: 85900624 | C170: VELKY TERMINAL | D170: KA PARTNERS | E170: 1GECO | F170: A | G170: GECO, a.s. | H170: 17. listopadu | I170: 3111 | J170: DVŮR KRÁLOVÉ NAD LABEM | K170: Trutnov | L170: RSE | M170: Lán Tomáš | N170: 50.427604 | O170: 15.817298 | P170: 216918.96
A171: 17616403 | B171: 87616403 | C171: VELKY TERMINAL | D171: KA PARTNERS | E171: 1LAG | F171: A | G171: Lagardere Travel Retail, a.s. | H171: Jeremenkova | I171: 103/23 | J171: OLOMOUC - HODOLANY | K171: Olomouc | L171: RSG | M171: Dolníček Richard | N171: 49.592520 | O171: 17.277739 | P171: 216616.46
A172: 14900210 | B172: 84900210 | C172: VELKY TERMINAL | D172: KA PARTNERS | E172: 1GECO | F172: A | G172: GECO, a.s. | H172: Polní | I172: 604/29 | J172: LIBEREC - LIBEREC XII-STARÉ PAVLOVICE | K172: Liberec | L172: RSD | M172: Luňáček Jan | N172: 50.782840 | O172: 15.039070 | P172: 216287.15
...

Sheet POS_STATUS_IMPORT
A1: POS | B1: ACTIVE

Sheet SALESAPP_IMPORT
A1: UID | B1: Date | C1: State | D1: Started at | E1: Finished at | F1: Real duration (h) | G1: Chain UID | H1: Chain | I1: Store UID | J1: Store | K1: Store address | L1: Agency region | M1: Executor UID | N1: Executor

Sheet MANAGER_PLAN
A1: WEEK | B1: DATE | C1: DAY | D1: TECHNICIAN | E1: POS | F1: KATEGORIE | G1: NAZEV_PROVOZOVNY | H1: ULICE | I1: CISLO | J1: MESTO | K1: OBLAST | L1: POS_AREA | M1: PPT | N1: LOS_ACTIVITY | O1: LOT_ACTIVITY | P1: REASON | Q1: GPS_GROUP

Sheet MANAGER_PLAN_PUBLISHED
A1: WEEK | B1: DATE | C1: DAY | D1: TECHNICIAN | E1: POS | F1: KATEGORIE | G1: NAZEV_PROVOZOVNY | H1: ULICE | I1: CISLO | J1: MESTO | K1: OBLAST | L1: POS_AREA | M1: PPT | N1: LOS_ACTIVITY | O1: LOT_ACTIVITY | P1: REASON | Q1: GPS_GROUP | R1: publishedAt

Sheet PLAN_LIFECYCLE
A1: year | B1: week | C1: status | D1: publishedAt | E1: closedAt

Sheet CONTROL
A1: SETTING | B1: VALUE | C1: DESCRIPTION
A2: CAMPAIGN_START_WEEK | B2: 31 | C2: Start kampane
A3: CAMPAIGN_LENGTH | B3: 4 | C3: Delka kampane tydny
A4: VISITS_PER_WEEK | B4: 40 | C4: Kapacita technika
A5: TARGET_VISITS_DAY | B5: 8 | C5: Doporuceny den
A6: NEARBY_EXTRA | B6: 5 | C6: Extra POS pobliz
A7: CANDIDATE_POOL | B7: 1.3 | C7: Rezerva pro GPS
A8: YEAR | B8: 2026
A9: SYNC_WINDOW_WEEKS | B9: 1
A10: PREMIUM_PERCENT | B10: 20
A11: NEARBY_EXTRA | B11: 5
A12: MAX_DISTANCE_KM | B12: 1
A13: PREMIUM_VISIT_GAP | B13: 2
A14: STANDARD_VISIT_GAP | B14: 8
A15: NEGLECTED_AFTER_WEEKS | B15: 26
A16: GPS_EXTRA_ENABLED | B16: 1 | C16: 1=on. Allows a small overflow beyond capacity for POS very close to an already-selected visit.
A17: GPS_EXTRA_RADIUS_METERS | B17: 300 | C17: Radius for the GPS bonus overflow rule.
A18: GPS_EXTRA_MAX_VISITS | B18: 5 | C18: Max extra visits per technician/week from the GPS bonus rule.
A19: COMPLIANCE_LATE_CUTOFF_WEEKS | B19: 1 | C19: Weeks past the planned week before a still-unrealized visit becomes Nesplneno instead of Pending. Proposed default per docs/BUSINESS_RULES.md section 12, not yet formally reconfirmed.
A20: ADVISOR_NEGLECT_WARNING_RATIO_PERCENT | B20: 80 | C20: Proposed default (not a confirmed business rule): WARNING neglect alert fires at this % of NEGLECTED_AFTER_WEEKS, CRITICAL fires at 100%. Tune on real data.
A21: ADVISOR_TREND_WINDOW_WEEKS | B21: 4 | C21: Proposed default: how many recent weeks of COMPLIANCE_LOG feed the technician/region overload alerts. Tune on real data.
A22: ADVISOR_OVERLOAD_WARNING_RATE_PERCENT | B22: 20 | C22: Proposed default (not a confirmed business rule): technician/region Nesplneno rate over the trend window that triggers a WARNING. Tune on real data.
A23: ADVISOR_OVERLOAD_CRITICAL_RATE_PERCENT | B23: 35 | C23: Proposed default (not a confirmed business rule): technician/region Nesplneno rate over the trend window that triggers a CRITICAL alert. Tune on real data.

Sheet MARKET_RULES
A1: MARKET | B1: ACTIVE
A2: IDT | B2: YES
A3: ČESKÁ POŠTA | B3: YES
A4: KA PARTNERS | B4: YES
A5: PETROL | B5: YES
A6: CORN | B6: YES

Sheet TERMINAL_RULES
A1: TYP TERMINALU | B1: ACTIVE
A2: VELKY TERMINAL | B2: YES
A3: SMALL TERMINAL | B3: NO
A4: LI | B4: NO

Sheet CATEGORY_RULES
A1: CATEGORY | B1: RULE
A2: STARTS_1 | B2: CORE
A3: 1FAST | B3: NORMAL
A4: 1CD | B4: EXCLUDE
A5: 1POSTA | B5: EXCLUDE
A6: * | B6: NORMAL

Sheet CADENCE_RULES
A1: ruleId | B1: scope | C1: matchValue | D1: minGapWeeks | E1: maxIntervalWeeks | F1: intervalType | G1: guaranteeType | H1: dedupBy | I1: campaignChangeOverride | J1: priority | K1: active | L1: validFrom | M1: validTo | N1: notes
A2: CORE | B2: categoryPrefix | C2: 1 | D2: 2 | F2: RECURRING | G2: SOFT_HIGH_WEIGHT | H2: NONE | I2: YES | J2: 90 | K2: YES | N2: Evolution of V10.5.5 score constant (CORE+=1e8). minGapWeeks=2 preserves PREMIUM_GAP with campaign-change override.
A3: MANDATORY_9PODNIK | B3: category | C3: 9PODNIKC;9PODNIKFC | F3: ONCE_PER_CAMPAIGN | G3: HARD | H3: ADDRESS | I3: NO | J3: 100 | K3: YES | N3: Preserves V10.5.5 mandatoryPodnik(): one guaranteed slot per campaign run, best-PTT POS per street+city.
A4: GECO | B4: category | C4: 1GECO | E4: 5 | F4: RECURRING | G4: HARD | H4: NONE | I4: NO | J4: 80 | K4: NO | N4: TODO: confirm scope (1GECO only vs whole KA PARTNERS market) and guaranteeType before activating. New for V11, no V10.5.5 precedent.
A5: CORN | B5: market | C5: CORN | E5: 4 | F5: RECURRING | G5: HARD | H5: NONE | I5: NO | J5: 80 | K5: NO | N5: TODO: confirm guaranteeType before activating (HARD proposed, 16 POS = negligible capacity impact). New for V11, no V10.5.5 precedent.

Sheet PARETO_GROUPS
A1: tierId | B1: name | C1: scope | D1: boundaryType | E1: boundaryValue | F1: active | G1: notes
A2: PREMIUM_TOP20 | B2: Premium (top 20% per portfolio) | C2: PER_TECHNICIAN | D2: PERCENTILE | E2: 20 | F2: YES | G2: Preserves V10.5.5 behaviour exactly (relative ranking within each technician's own portfolio). Scope field kept switchable to GLOBAL / PER_REGION / PER_MARKET for a later decision, not activated now.
A3: KA | B3: KA (business-significant outlets) | F3: NO | G3: TODO: scope + threshold not yet confirmed (BUSINESS_RULES.md).
A4: IDT_ABOVE_THRESHOLD | B4: IDT above PPT threshold | F4: NO | G4: TODO: boundaryType/scope not yet confirmed (BUSINESS_RULES.md).

Sheet SCORE_PROFILES
A1: profileId | B1: component | C1: weight | D1: notes
A2: DEFAULT | B2: CORE | C2: 100000000 | D2: Preserves V10.5.5 magnitude as-is; normalize later.
A3: DEFAULT | B3: KATEGORIZACE_A | C3: 10000000 | D3: Preserves V10.5.5 magnitude as-is.
A4: DEFAULT | B4: PPT | C4: 1 | D4: Raw PTT value, unweighted (as in V10.5.5).
A5: DEFAULT | B5: NEGLECTED_BONUS | C5: 50000 | D5: Applied when weeksSinceLastVisit >= NEGLECTED_AFTER_WEEKS.

Sheet ADVISOR_RULES
A1: ruleId | B1: type | C1: condition | D1: threshold | E1: severity | F1: messageTemplate | G1: active

Sheet CAPACITY_OVERRIDE
A1: technician | B1: year | C1: week | D1: capacity

Sheet COMPLIANCE_LOG
A1: posId | B1: technician | C1: plannedWeek | D1: plannedYear | E1: status | F1: matchedActualDate | G1: matchedActualWeek | H1: evaluatedAt

Sheet ADVISOR_LOG
A1: type | B1: severity | C1: subjectType | D1: subjectId | E1: message | F1: evaluatedAt

Sheet VISIT_HISTORY_ACTUAL
A1: posId | B1: date | C1: week | D1: year | E1: executor | F1: state | G1: salesAppUid

Sheet VISIT_HISTORY
A1: POS | B1: WEEK | C1: YEAR | D1: LOS_ACTIVITY | E1: LOT_ACTIVITY | F1: TECHNICIAN
A2: 81902616 | B2: 31 | C2: 2026 | D2: Gems | E2: Sportka | F2: Myslivec Jan
A3: 81601020 | B3: 31 | C3: 2026 | D3: Gems | E3: Sportka | F3: Myslivec Jan
A4: 81915409 | B4: 31 | C4: 2026 | D4: Gems | E4: Sportka | F4: Myslivec Jan
A5: 81510001 | B5: 31 | C5: 2026 | D5: Gems | E5: Sportka | F5: Myslivec Jan
A6: 81526530 | B6: 31 | C6: 2026 | D6: Gems | E6: Sportka | F6: Myslivec Jan
A7: 81915451 | B7: 31 | C7: 2026 | D7: Gems | E7: Sportka | F7: Myslivec Jan
A8: 81757705 | B8: 31 | C8: 2026 | D8: Gems | E8: Sportka | F8: Myslivec Jan
A9: 81601049 | B9: 31 | C9: 2026 | D9: Gems | E9: Sportka | F9: Myslivec Jan
A10: 81902615 | B10: 31 | C10: 2026 | D10: Gems | E10: Sportka | F10: Myslivec Jan
A11: 81915410 | B11: 31 | C11: 2026 | D11: Gems | E11: Sportka | F11: Myslivec Jan
A12: 81601014 | B12: 31 | C12: 2026 | D12: Gems | E12: Sportka | F12: Myslivec Jan
A13: 81902643 | B13: 31 | C13: 2026 | D13: Gems | E13: Sportka | F13: Myslivec Jan
... A4321: 83731501 | B4321: 34 | C4321: 2026 | D4321: Gems | E4321: Sportka | F4321: Horejš Vladimír
